Workbook

Sheet Facilities
A1: facility_name | B1: operator | C1: operator_family | D1: city | E1: state | F1: cea_grid_region | G1: capacity_mw | H1: capacity_basis | I1: status | J1: area_sqft | K1: confidence | L1: source_url | M1: notes | N1: op_capacity_mw
A2: CtrlS Mumbai DC1/DC2 (Nine Zone) | B2: CtrlS | C2: CtrlS | D2: Mumbai | E2: Maharashtra | F2: Western | G2: 40 | H2: combined | I2: Operational | K2: Med | L2: https://www.ctrls.com/datacenters-in-india/ | M2: Combined DC1+DC2 disclosed | N2: =IF(AND(I2="Operational",OR(H2="operational_IT",H2="operational_critical",H2="operational_total",H2="combined")),G2,"") -> 40
A3: CtrlS Mumbai DC3 | B3: CtrlS | C3: CtrlS | D3: Mumbai | E3: Maharashtra | F3: Western | G3: 10 | H3: operational_total | I3: Operational | K3: Med | L3: https://www.ctrls.com/datacenters-in-india/ | N3: =IF(AND(I3="Operational",OR(H3="operational_IT",H3="operational_critical",H3="operational_total",H3="combined")),G3,"") -> 10
A4: CtrlS Mumbai DC4 | B4: CtrlS | C4: CtrlS | D4: Mumbai | E4: Maharashtra | F4: Western | G4: 36.8 | H4: operational_total | I4: Operational | J4: 265000 | K4: High | L4: https://baxtel.com/data-centers/ctrls-datacenters-ltd | M4: 2936 racks corroborated | N4: =IF(AND(I4="Operational",OR(H4="operational_IT",H4="operational_critical",H4="operational_total",H4="combined")),G4,"") -> 36.8
A5: CtrlS Mumbai DC5 | B5: CtrlS | C5: CtrlS | D5: Mumbai | E5: Maharashtra | F5: Western | G5: 32 | H5: operational_total | I5: Operational | J5: 228482 | K5: High | L5: https://baxtel.com/data-centers/ctrls-datacenters-ltd | M5: 2750 racks corroborated | N5: =IF(AND(I5="Operational",OR(H5="operational_IT",H5="operational_critical",H5="operational_total",H5="combined")),G5,"") -> 32
A6: CtrlS Navi Mumbai DC6/DC7 | B6: CtrlS | C6: CtrlS | D6: Navi Mumbai | E6: Maharashtra | F6: Western | G6: 95 | H6: planned | I6: Under-construction | K6: Med | L6: https://www.ctrls.com/datacenters-in-india/ | M6: Combined planned | N6: =IF(AND(I6="Operational",OR(H6="operational_IT",H6="operational_critical",H6="operational_total",H6="combined")),G6,"")
A7: CtrlS Hyderabad DC1 | B7: CtrlS | C7: CtrlS | D7: Hyderabad | E7: Telangana | F7: Southern | G7: 6 | H7: operational_total | I7: Operational | J7: 191749 | K7: Med | L7: https://www.ctrls.com/datacenters-in-india/ | N7: =IF(AND(I7="Operational",OR(H7="operational_IT",H7="operational_critical",H7="operational_total",H7="combined")),G7,"") -> 6
A8: CtrlS Hyderabad DC2 | B8: CtrlS | C8: CtrlS | D8: Hyderabad | E8: Telangana | F8: Southern | G8: 7.4 | H8: operational_total | I8: Operational | J8: 82262 | K8: Med | L8: https://www.ctrls.com/datacenters-in-india/ | N8: =IF(AND(I8="Operational",OR(H8="operational_IT",H8="operational_critical",H8="operational_total",H8="combined")),G8,"") -> 7.4
A9: CtrlS Hyderabad DC3 | B9: CtrlS | C9: CtrlS | D9: Hyderabad | E9: Telangana | F9: Southern | G9: 13 | H9: operational_total | I9: Operational | J9: 130000 | K9: Med | L9: https://www.ctrls.com/datacenters-in-india/ | N9: =IF(AND(I9="Operational",OR(H9="operational_IT",H9="operational_critical",H9="operational_total",H9="combined")),G9,"") -> 13
A10: CtrlS Chandan Valley Campus | B10: CtrlS | C10: CtrlS | D10: Hyderabad | E10: Telangana | F10: Southern | H10: planned | I10: Announced | J10: 1612700 | K10: Low | L10: https://www.datacenterdynamics.com/en/news/ctrls-to-build-40-acre-data-center-campus-near-hyderabad-india/ | M10: 6 buildings planned | N10: =IF(AND(I10="Operational",OR(H10="operational_IT",H10="operational_critical",H10="operational_total",H10="combined")),G10,"")
A11: CtrlS Chennai DC2 | B11: CtrlS | C11: CtrlS | D11: Chennai | E11: Tamil Nadu | F11: Southern | H11: unknown | I11: Operational | J11: 290000 | K11: Med | L11: https://baxtel.com/data-centers/ctrls-datacenters-ltd | N11: =IF(AND(I11="Operational",OR(H11="operational_IT",H11="operational_critical",H11="operational_total",H11="combined")),G11,"")
A12: CtrlS Chennai DC Park | B12: CtrlS | C12: CtrlS | D12: Chennai | E12: Tamil Nadu | F12: Southern | H12: park | I12: Operational | J12: 1000000 | K12: Med | L12: https://baxtel.com/data-centers/ctrls-datacenters-ltd | M12: Campus total sqft | N12: =IF(AND(I12="Operational",OR(H12="operational_IT",H12="operational_critical",H12="operational_total",H12="combined")),G12,"")
A13: CtrlS Chennai DC3 | B13: CtrlS | C13: CtrlS | D13: Chennai | E13: Tamil Nadu | F13: Southern | H13: unknown | I13: Announced | K13: Low | L13: https://baxtel.com/data-centers/ctrls-datacenters-ltd | M13: Single directory source | N13: =IF(AND(I13="Operational",OR(H13="operational_IT",H13="operational_critical",H13="operational_total",H13="combined")),G13,"")
A14: CtrlS Noida DC1 | B14: CtrlS | C14: CtrlS | D14: Noida | E14: Uttar Pradesh | F14: Northern | H14: unknown | I14: Operational | K14: Med | L14: https://www.ctrls.com/datacenter-noida/ | N14: =IF(AND(I14="Operational",OR(H14="operational_IT",H14="operational_critical",H14="operational_total",H14="combined")),G14,"")
A15: CtrlS Bangalore DC1 | B15: CtrlS | C15: CtrlS | D15: Bengaluru | E15: Karnataka | F15: Southern | H15: unknown | I15: Operational | K15: Med | L15: https://www.ctrls.com/datacenter-bangalore/ | N15: =IF(AND(I15="Operational",OR(H15="operational_IT",H15="operational_critical",H15="operational_total",H15="combined")),G15,"")
A16: CtrlS Kolkata DC1 | B16: CtrlS | C16: CtrlS | D16: Kolkata | E16: West Bengal | F16: Eastern | H16: unknown | I16: Operational | K16: Med | L16: https://www.businessworld.in/article/ctrls-opens-kolkata-data-centre-567186 | N16: =IF(AND(I16="Operational",OR(H16="operational_IT",H16="operational_critical",H16="operational_total",H16="combined")),G16,"")
A17: CtrlS Kolkata Campus | B17: CtrlS | C17: CtrlS | D17: Kolkata | E17: West Bengal | F17: Eastern | G17: 60 | H17: planned | I17: Announced | K17: Med | L17: https://www.datacenterdynamics.com/en/news/indias-ctrls-datacenters-to-build-data-center-campus-in-kolkata/ | M17: Rs2200cr | N17: =IF(AND(I17="Operational",OR(H17="operational_IT",H17="operational_critical",H17="operational_total",H17="combined")),G17,"")
A18: CtrlS Patna Edge DC1 | B18: CtrlS | C18: CtrlS | D18: Patna | E18: Bihar | F18: Eastern | G18: 0.5 | H18: operational_total | I18: Operational | K18: Med | L18: https://www.ctrls.com/datacenters-in-india/ | N18: =IF(AND(I18="Operational",OR(H18="operational_IT",H18="operational_critical",H18="operational_total",H18="combined")),G18,"") -> 0.5
A19: CtrlS Patna Edge DC2 | B19: CtrlS | C19: CtrlS | D19: Patna | E19: Bihar | F19: Eastern | G19: 11.6 | H19: operational_total | I19: Operational | K19: Med | L19: https://www.ctrls.com/datacenters-in-india/ | N19: =IF(AND(I19="Operational",OR(H19="operational_IT",H19="operational_critical",H19="operational_total",H19="combined")),G19,"") -> 11.6
A20: CtrlS Lucknow Edge DC | B20: CtrlS | C20: CtrlS | D20: Lucknow | E20: Uttar Pradesh | F20: Northern | G20: 0.2 | H20: operational_total | I20: Operational | K20: Med | L20: https://www.ctrls.com/datacenters-in-india/ | N20: =IF(AND(I20="Operational",OR(H20="operational_IT",H20="operational_critical",H20="operational_total",H20="combined")),G20,"") -> 0.2
A21: CtrlS Ahmedabad Edge DC | B21: CtrlS | C21: CtrlS | D21: Ahmedabad | E21: Gujarat | F21: Western | G21: 9.2 | H21: operational_total | I21: Operational | K21: Med | L21: https://www.ctrls.com/datacenters-in-india/ | N21: =IF(AND(I21="Operational",OR(H21="operational_IT",H21="operational_critical",H21="operational_total",H21="combined")),G21,"") -> 9.2
A22: CtrlS GIFT City DC | B22: CtrlS | C22: CtrlS | D22: Gandhinagar | E22: Gujarat | F22: Western | H22: planned | I22: Under-construction | K22: Med | L22: https://www.datacenterdynamics.com/en/news/ctrls-breaks-ground-on-data-center-in-gujarat-india-to-invest-30m-in-project/ | M22: $30M | N22: =IF(AND(I22="Operational",OR(H22="operational_IT",H22="operational_critical",H22="operational_total",H22="combined")),G22,"")
A23: CtrlS Bhopal DC | B23: CtrlS | C23: CtrlS | D23: Bhopal | E23: Madhya Pradesh | F23: Western | H23: planned | I23: Announced | K23: Med | L23: https://telecomtalk.info/ctrls-invest-rs500-crore-greenfield-datacentre-bhopal/993442/ | M23: Rs500cr | N23: =IF(AND(I23="Operational",OR(H23="operational_IT",H23="operational_critical",H23="operational_total",H23="combined")),G23,"")
A24: CtrlS Guwahati DC | B24: CtrlS | C24: CtrlS | D24: Guwahati | E24: Assam | F24: North-Eastern | H24: planned | I24: Under-construction | K24: Med | L24: https://www.datacenterdynamics.com/en/news/ctrls-breaks-ground-on-new-data-center-in-guwahati-assam/ | N24: =IF(AND(I24="Operational",OR(H24="operational_IT",H24="operational_critical",H24="operational_total",H24="combined")),G24,"")
A25: CtrlS Bhubaneswar Edge | B25: CtrlS | C25: CtrlS | D25: Bhubaneswar | E25: Odisha | F25: Eastern | H25: unknown | I25: Announced | K25: Low | L25: https://baxtel.com/data-centers/ctrls-datacenters-ltd | M25: Single source | N25: =IF(AND(I25="Operational",OR(H25="operational_IT",H25="operational_critical",H25="operational_total",H25="combined")),G25,"")
A26: CtrlS Kochi Edge | B26: CtrlS | C26: CtrlS | D26: Kochi | E26: Kerala | F26: Southern | H26: unknown | I26: Announced | K26: Low | L26: https://baxtel.com/data-centers/ctrls-datacenters-ltd | M26: Single source | N26: =IF(AND(I26="Operational",OR(H26="operational_IT",H26="operational_critical",H26="operational_total",H26="combined")),G26,"")
A27: Yotta NM1 | B27: Yotta | C27: Yotta | D27: Navi Mumbai | E27: Maharashtra | F27: Western | G27: 52 | H27: operational_IT | I27: Operational | K27: High | L27: https://yotta.com/ | M27: ~7000 racks | N27: =IF(AND(I27="Operational",OR(H27="operational_IT",H27="operational_critical",H27="operational_total",H27="combined")),G27,"") -> 52
A28: Yotta NM2 | B28: Yotta | C28: Yotta | D28: Navi Mumbai | E28: Maharashtra | F28: Western | H28: planned | I28: Under-construction | K28: Med | L28: https://colocation.yotta.com/data-center/ | M28: Core and shell ready | N28: =IF(AND(I28="Operational",OR(H28="operational_IT",H28="operational_critical",H28="operational_total",H28="combined")),G28,"")
A29: Yotta D1 Shakti (Greater Noida) | B29: Yotta | C29: Yotta | D29: Greater Noida | E29: Uttar Pradesh | F29: Northern | G29: 30 | H29: operational_total | I29: Operational | J29: 300000 | K29: High | L29: https://www.datacenterdynamics.com/en/news/yotta-launches-data-center-in-noida-india/ | M29: 5000 racks | N29: =IF(AND(I29="Operational",OR(H29="operational_IT",H29="operational_critical",H29="operational_total",H29="combined")),G29,"") -> 30
A30: Yotta G1 (GIFT City) | B30: Yotta | C30: Yotta | D30: Gandhinagar | E30: Gujarat | F30: Western | G30: 2 | H30: operational_total | I30: Operational | J30: 21000 | K30: High | L30: https://colocation.yotta.com/data-center/ | M30: 350 racks | N30: =IF(AND(I30="Operational",OR(H30="operational_IT",H30="operational_critical",H30="operational_total",H30="combined")),G30,"") -> 2
A31: Yotta Chennai DC Park | B31: Yotta | C31: Yotta | D31: Chennai | E31: Tamil Nadu | F31: Southern | G31: 140 | H31: planned | I31: Under-construction | K31: Med | L31: https://colocation.yotta.com/data-center/ | M31: 25000 racks planned | N31: =IF(AND(I31="Operational",OR(H31="operational_IT",H31="operational_critical",H31="operational_total",H31="combined")),G31,"")
A32: Sify Mumbai 01 (Vashi) | B32: Sify | C32: Sify | D32: Navi Mumbai | E32: Maharashtra | F32: Western | H32: unknown | I32: Operational | K32: Med | L32: https://baxtel.com/data-centers/sify-technologies | N32: =IF(AND(I32="Operational",OR(H32="operational_IT",H32="operational_critical",H32="operational_total",H32="combined")),G32,"")
A33: Sify Mumbai 02 (Airoli) | B33: Sify | C33: Sify | D33: Navi Mumbai | E33: Maharashtra | F33: Western | H33: unknown | I33: Operational | K33: Med | L33: https://baxtel.com/data-centers/sify-technologies | M33: 1345 racks | N33: =IF(AND(I33="Operational",OR(H33="operational_IT",H33="operational_critical",H33="operational_total",H33="combined")),G33,"")
A34: Sify Rabale DC Park (Mumbai 03) | B34: Sify | C34: Sify | D34: Navi Mumbai | E34: Maharashtra | F34: Western | G34: 85 | H34: operational_IT | I34: Operational | K34: High | L34: https://www.sifytechnologies.com/data-center/rabale-data-center/ | M34: 5 towers live; low end of 85-97 range; scaling to 185+ | N34: =IF(AND(I34="Operational",OR(H34="operational_IT",H34="operational_critical",H34="operational_total",H34="combined")),G34,"") -> 85
A35: Sify Noida 01 | B35: Sify | C35: Sify | D35: Noida | E35: Uttar Pradesh | F35: Northern | H35: unknown | I35: Operational | K35: Med | L35: https://baxtel.com/data-centers/sify-technologies | M35: 2100 racks | N35: =IF(AND(I35="Operational",OR(H35="operational_IT",H35="operational_critical",H35="operational_total",H35="combined")),G35,"")
A36: Sify Noida 02 Campus | B36: Sify | C36: Sify | D36: Noida | E36: Uttar Pradesh | F36: Northern | G36: 25.92 | H36: operational_IT | I36: Operational | K36: High | L36: https://www.sifytechnologies.com/data-center/noida02-data-center/ | M36: Campus target 78MW | N36: =IF(AND(I36="Operational",OR(H36="operational_IT",H36="operational_critical",H36="operational_total",H36="combined")),G36,"") -> 25.92
A37: Sify Bangalore 01 | B37: Sify | C37: Sify | D37: Bengaluru | E37: Karnataka | F37: Southern | H37: unknown | I37: Operational | K37: Med | L37: https://baxtel.com/data-centers/sify-technologies | M37: 600+ racks | N37: =IF(AND(I37="Operational",OR(H37="operational_IT",H37="operational_critical",H37="operational_total",H37="combined")),G37,"")
A38: Sify Bangalore 02 | B38: Sify | C38: Sify | D38: Bengaluru | E38: Karnataka | F38: Southern | H38: planned | I38: Announced | K38: Low | L38: https://baxtel.com/data-centers/sify-technologies | N38: =IF(AND(I38="Operational",OR(H38="operational_IT",H38="operational_critical",H38="operational_total",H38="combined")),G38,"")
A39: Sify Hyderabad 1 | B39: Sify | C39: Sify | D39: Hyderabad | E39: Telangana | F39: Southern | H39: unknown | I39: Operational | K39: Med | L39: https://baxtel.com/data-centers/sify-technologies | M39: 2400 racks | N39: =IF(AND(I39="Operational",OR(H39="operational_IT",H39="operational_critical",H39="operational_total",H39="combined")),G39,"")
A40: Sify Hyderabad 2 Campus | B40: Sify | C40: Sify | D40: Hyderabad | E40: Telangana | F40: Southern | G40: 250 | H40: planned | I40: Announced | K40: Low | L40: https://baxtel.com/data-centers/sify-technologies | N40: =IF(AND(I40="Operational",OR(H40="operational_IT",H40="operational_critical",H40="operational_total",H40="combined")),G40,"")
...

Sheet Summary
A1: India Datacenter Facilities — Coverage Summary (v0)
A2: Assembled 2026-09-14 from operator disclosures + trade press + public directories (4 parallel web sweeps). Counts/sums are live formulas over the Facilities tab.
A4: Counts by status
A5: Total rows in dataset | B5: =COUNTA(Facilities!A2:A500) -> 194
A6: Operational | B6: =COUNTIF(Facilities!I2:I500,"Operational") -> 129
A7: Under-construction | B7: =COUNTIF(Facilities!I2:I500,"Under-construction") -> 37
A8: Announced | B8: =COUNTIF(Facilities!I2:I500,"Announced") -> 24
A9: Uncertain | B9: =COUNTIF(Facilities!I2:I500,"Uncertain") -> 4
A10: Rows with a disclosed MW figure | B10: =COUNT(Facilities!G2:G500) -> 134
A12: Disclosed capacity (MW)
A13: Operational disclosed MW (IT/critical/total/combined) | B13: =SUM(Facilities!N2:N500) -> 1373.42
A14: of which Operational IT-only MW | B14: =SUMIFS(Facilities!G2:G500,Facilities!I2:I500,"Operational",Facilities!H2:H500,"operational_IT") -> 812.12
A15: of which Operational critical-IT MW | B15: =SUMIFS(Facilities!G2:G500,Facilities!I2:I500,"Operational",Facilities!H2:H500,"operational_critical") -> 172.9
A16: Announced/under-construction pipeline MW (planned) | B16: =SUMIFS(Facilities!G2:G500,Facilities!H2:H500,"planned") -> 8648
A18: Facilities by CEA grid region (excl. cloud regions/parks)
A19: Western (MH/GJ/MP) | B19: =COUNTIFS(Facilities!F2:F500,"Western",Facilities!H2:H500,"<>region",Facilities!H2:H500,"<>park",Facilities!H2:H500,"<>edge") -> 77
A20: Southern (TN/TG/KA/AP/KL) | B20: =COUNTIFS(Facilities!F2:F500,"Southern",Facilities!H2:H500,"<>region",Facilities!H2:H500,"<>park",Facilities!H2:H500,"<>edge") -> 60
A21: Northern (UP/DL/HR/RJ/PB/CH) | B21: =COUNTIFS(Facilities!F2:F500,"Northern",Facilities!H2:H500,"<>region",Facilities!H2:H500,"<>park",Facilities!H2:H500,"<>edge") -> 30
A22: Eastern (WB/BR/OD) | B22: =COUNTIFS(Facilities!F2:F500,"Eastern",Facilities!H2:H500,"<>region",Facilities!H2:H500,"<>park",Facilities!H2:H500,"<>edge") -> 12
A23: North-Eastern (AS) | B23: =COUNTIFS(Facilities!F2:F500,"North-Eastern",Facilities!H2:H500,"<>region",Facilities!H2:H500,"<>park",Facilities!H2:H500,"<>edge") -> 1
A25: Rows by operator family (top operators)
A26: STT GDC India | B26: =COUNTIF(Facilities!C2:C500,"STT GDC India") -> 34
A27: Nxtra by Airtel | B27: =COUNTIF(Facilities!C2:C500,"Nxtra by Airtel") -> 25
A28: CtrlS | B28: =COUNTIF(Facilities!C2:C500,"CtrlS") -> 25
A29: NTT Global Data Centers | B29: =COUNTIF(Facilities!C2:C500,"NTT Global Data Centers") -> 16
A30: Sify | B30: =COUNTIF(Facilities!C2:C500,"Sify") -> 16
A31: Web Werks / Iron Mountain JV | B31: =COUNTIF(Facilities!C2:C500,"Web Werks / Iron Mountain JV") -> 10
A33: Cloud regions (region-level, not single facilities) | B33: =COUNTIF(Facilities!H2:H500,"region") -> 10

Sheet Notes & Method
A1: India Datacenter Facilities v0 — method, dedup rules & caveats
A3: What this is
A4: A first, openly-sourced, facility-level list of India datacenters, assembled 2026-09-14 from operator websites, trade press (DataCenterDynamics, w.media), and public directories (DataCenterMap, Baxtel). Every row carries its source_url and a confidence flag. This is the DERIVE facility layer for the paper's S0 join — a curated set, disclosed as such, NOT a purchased commercial dataset.
A6: Deduplication rules applied
A7: Web Werks = Iron Mountain: the Web Werks facilities and Iron Mountain India are the SAME JV; listed once under Iron Mountain branding.
A8: Digital Connexion = Digital Realty + Brookfield + Reliance/Jio: listed once under 'Digital Connexion'; may appear elsewhere under Digital Realty.
A9: Google Vizag = AdaniConneX Vizag: the same campus (Google $15B + AdaniConneX build); listed once (AdaniConneX row), not double-counted under Google.
A10: Meta Jamnagar = Reliance Jamnagar: Meta leases capacity in Reliance's Jamnagar campus; listed once (Reliance row).
A11: Tata Communications legacy sites = STT GDC India: the former Tata Comms DC business is now STT GDC India; only the authoritative STT GDC rows are kept; the legacy directory rows were dropped.
A12: TCS HyperVault (OpenAI partner) is a DISTINCT Tata Group entity from STT GDC — kept as one separate announced row.
A14: Capacity caveats (read before summing)
A15: capacity_basis tags what each MW figure means: operational_IT / operational_critical / operational_total / combined / planned / region / park / edge / estimate.
... A25: Aggregate cross-checks (for coverage %): DataCenterMap ~303-305 facilities; CEEW (Jan 2026) ~271 DCs / ~1.5GW; Savills ~1.5GW operational end-2025; CBRE ~1,700MW operational end-2025; Arizton 142 existing + 110 upcoming.
